Workbook

Sheet Subcategory Scores
A1: Function | B1: Category ID | C1: Category Name | D1: Subcategory ID | E1: Subcategory Outcome (NIST CSF 2.0) | F1: CMMI Score (1-5) | G1: Controls In Place (Northwind) | H1: Primary Evidence Document | I1: Residual Client Question
A2: Govern | B2: GV.OC | C2: Organizational Context | D2: GV.OC-01 | E2: The organizational mission is understood and informs cybersecurity risk management | F2: 3 | G2: Cybersecurity risk management is explicitly referenced in Northwind's group strategy documents and board-level risk appetite statement, linking cyber risk to the retail banking and general insurance business plans. | H2: Group Risk Management Strategy
A3: Govern | B3: GV.OC | C3: Organizational Context | D3: GV.OC-02 | E3: Internal and external stakeholders are understood, and their needs and expectations regarding cybersecurity risk management are understood and considered | F3: 3 | G3: Stakeholder needs (retail and insurance customers, PRA, FCA, regulators, shareholders) are catalogued in a stakeholder register reviewed annually by the Compliance Officer. | H3: Stakeholder Register / Info Sec Policy intro
A4: Govern | B4: GV.OC | C4: Organizational Context | D4: GV.OC-03 | E4: Legal, regulatory, and contractual requirements regarding cybersecurity — including privacy and civil liberties obligations — are understood and managed | F4: 3 | G4: The Compliance Officer maintains a documented, dated inventory of applicable regulatory requirements (UK GDPR, PRA/FCA Operational Resilience, SYSC 8/13, SM&CR); no formal line-item mapping exists yet from each requirement to a specific internal control. | H4: Regulatory Requirements Register | I4: Can you show a mapping from a specific PRA/FCA requirement to an internal control?
A5: Govern | B5: GV.OC | C5: Organizational Context | D5: GV.OC-04 | E5: Critical objectives, capabilities, and services that external stakeholders depend on or expect from the organization are understood and communicated | F5: 3 | G5: Critical services relied upon by customers and regulators (current accounts, claims processing) are documented in the Operational Resilience 'important business services' register. | H5: Operational Resilience Policy / Important Business Services Register
A6: Govern | B6: GV.OC | C6: Organizational Context | D6: GV.OC-05 | E6: Outcomes, capabilities, and services that the organization depends on are understood and communicated | F6: 3 | G6: Dependencies on the legacy core banking platform and the SaaS insurance platform are documented as part of the important business services mapping. | H6: Operational Resilience Policy
A7: Govern | B7: GV.RM | C7: Risk Management Strategy | D7: GV.RM-01 | E7: Risk management objectives are established and agreed to by organizational stakeholders | F7: 3 | G7: Risk management objectives are agreed annually by the Board Risk Committee and cascaded to BU heads. | H7: Risk Management Strategy
A8: Govern | B8: GV.RM | C8: Risk Management Strategy | D8: GV.RM-02 | E8: Risk appetite and risk tolerance statements are established, communicated, and maintained | F8: 3 | G8: Risk appetite and tolerance statements exist and are reviewed annually, though tolerance is expressed qualitatively rather than against quantified impact tolerances for all important business services. | H8: Risk Appetite Statement
A9: Govern | B9: GV.RM | C9: Risk Management Strategy | D9: GV.RM-03 | E9: Cybersecurity risk management activities and outcomes are included in enterprise risk management processes | F9: 3 | G9: Cyber risk is a standing line item in the enterprise risk register reviewed by the Board Risk Committee. | H9: Enterprise Risk Register
A10: Govern | B10: GV.RM | C10: Risk Management Strategy | D10: GV.RM-04 | E10: Strategic direction that describes appropriate risk response options is established and communicated | F10: 3 | G10: Strategic risk response options (accept/mitigate/transfer/avoid) are documented in the risk management strategy and applied by the Compliance Officer and CISO. | H10: Risk Management Strategy
A11: Govern | B11: GV.RM | C11: Risk Management Strategy | D11: GV.RM-05 | E11: Lines of communication across the organization are established for cybersecurity risks, including risks from suppliers and other third parties | F11: 3 | G11: Lines of communication for cyber risk, including supplier-originated risk, run through the CISO to the Board Risk Committee. | H11: Governance / Escalation Chart
A12: Govern | B12: GV.RM | C12: Risk Management Strategy | D12: GV.RM-06 | E12: A standardized method for calculating, documenting, categorizing, and prioritizing cybersecurity risks is established and communicated | F12: 3 | G12: A standardised risk scoring methodology (likelihood x impact matrix) is documented and applied consistently across BUs. | H12: Risk Management Strategy / Risk Register methodology appendix
A13: Govern | B13: GV.RM | C13: Risk Management Strategy | D13: GV.RM-07 | E13: Strategic opportunities (i.e., positive risks) are characterized and are included in organizational cybersecurity risk discussions | F13: 3 | G13: Positive/strategic opportunities are noted qualitatively in risk committee papers but not yet tracked as a discrete category alongside negative risk. | H13: Board Risk Committee minutes
A14: Govern | B14: GV.RR | C14: Roles, Responsibilities, and Authorities | D14: GV.RR-01 | E14: Organizational leadership is responsible and accountable for cybersecurity risk and fosters a culture that is risk-aware, ethical, and continually improving | F14: 4 | G14: Under SM&CR, the CISO holds a Senior Manager Function with personal statutory accountability for cyber risk, formally recorded in the Statement of Responsibilities and reinforced through board-level tone-from-the-top messaging. | H14: SM&CR Statement of Responsibilities
A15: Govern | B15: GV.RR | C15: Roles, Responsibilities, and Authorities | D15: GV.RR-02 | E15: Roles, responsibilities, and authorities related to cybersecurity risk management are established, communicated, understood, and enforced | F15: 4 | G15: Cybersecurity roles and responsibilities are documented in the Info Sec Policy and RACI matrix, communicated to all BU heads, and enforced through job descriptions. | H15: Info Sec Policy / RACI Matrix
A16: Govern | B16: GV.RR | C16: Roles, Responsibilities, and Authorities | D16: GV.RR-03 | E16: Adequate resources are allocated commensurate with the cybersecurity risk strategy, roles, responsibilities, and policies | F16: 3 | G16: Cybersecurity budget and headcount are allocated annually against the risk strategy, though resourcing for the legacy core banking security function is comparatively thin versus the newer insurance platform team. | H16: Annual Budget Papers | J16: Doesn't look too important for an evidence- can skip, may affect the maturity of the control but should be ok
A17: Govern | B17: GV.RR | C17: Roles, Responsibilities, and Authorities | D17: GV.RR-04 | E17: Cybersecurity is included in human resources practices | F17: 3 | G17: Cybersecurity responsibilities are included in job descriptions and onboarding/offboarding checklists managed by HR. | H17: HR Security Policy
A18: Govern | B18: GV.PO | C18: Policy | D18: GV.PO-01 | E18: Policy for managing cybersecurity risks is established based on organizational context, cybersecurity strategy, and priorities and is communicated and enforced | F18: 4 | G18: A Board-approved Information Security Policy establishes cybersecurity policy based on organisational context and strategy, communicated to all staff and enforced through the disciplinary policy. | H18: Info Sec Policy
A19: Govern | B19: GV.PO | C19: Policy | D19: GV.PO-02 | E19: Policy for managing cybersecurity risks is reviewed, updated, communicated, and enforced to reflect changes in requirements, threats, technology, and organizational mission | F19: 3 | G19: Policy review is scheduled annually, though the most recent Info Sec Policy review lags roughly six months behind the stated cadence. | H19: Info Sec Policy version history
A20: Govern | B20: GV.OV | C20: Oversight | D20: GV.OV-01 | E20: Cybersecurity risk management strategy outcomes are reviewed to inform and adjust strategy and direction | F20: 3 | G20: Cyber risk management outcomes are reported to the Board Risk Committee quarterly and used to adjust the risk strategy. | H20: Board Risk Committee papers
A21: Govern | B21: GV.OV | C21: Oversight | D21: GV.OV-02 | E21: The cybersecurity risk management strategy is reviewed and adjusted to ensure coverage of organizational requirements and risks | F21: 3 | G21: The risk management strategy is reviewed annually against emerging requirements, including Operational Resilience impact tolerance testing results. | H21: Risk Management Strategy review log
A22: Govern | B22: GV.OV | C22: Oversight | D22: GV.OV-03 | E22: Organizational cybersecurity risk management performance is evaluated and reviewed for adjustments needed | F22: 3 | G22: Cybersecurity programme performance is evaluated annually via an internal audit review, though findings-closure tracking is informal. | H22: Internal Audit Report
A23: Govern | B23: GV.SC | C23: Cybersecurity Supply Chain Risk Management | D23: GV.SC-01 | E23: A cybersecurity supply chain risk management program, strategy, objectives, policies, and processes are established and agreed to by organizational stakeholders | F23: 3 | G23: A documented cyber supply chain risk management programme and policy exist and are agreed by BU heads. | H23: Vendor Risk Management Policy
A24: Govern | B24: GV.SC | C24: Cybersecurity Supply Chain Risk Management | D24: GV.SC-02 | E24: Cybersecurity roles and responsibilities for suppliers, customers, and partners are established, communicated, and coordinated internally and externally | F24: 3 | G24: Cybersecurity roles for suppliers, including the core banking hosting provider and the SaaS insurance vendor, are defined in the Vendor Risk Management Policy. | H24: Vendor Risk Management Policy
A25: Govern | B25: GV.SC | C25: Cybersecurity Supply Chain Risk Management | D25: GV.SC-03 | E25: Cybersecurity supply chain risk management is integrated into cybersecurity and enterprise risk management, risk assessment, and improvement processes | F25: 3 | G25: Supply chain risk is integrated into the enterprise risk register as a distinct risk category. | H25: Enterprise Risk Register
A26: Govern | B26: GV.SC | C26: Cybersecurity Supply Chain Risk Management | D26: GV.SC-04 | E26: Suppliers are known and prioritized by criticality | F26: 3 | G26: Suppliers are catalogued and tiered by criticality in the vendor list (10 vendors, criticality-tiered). | H26: Vendor List
A27: Govern | B27: GV.SC | C27: Cybersecurity Supply Chain Risk Management | D27: GV.SC-05 | E27: Requirements to address cybersecurity risks in supply chains are established, prioritized, and integrated into contracts and other types of agreements with suppliers and other relevant third parties | F27: 3 | G27: Cybersecurity clauses are built into standard contract templates for new supplier agreements. | H27: Standard Supplier Contract Template
A28: Govern | B28: GV.SC | C28: Cybersecurity Supply Chain Risk Management | D28: GV.SC-06 | E28: Planning and due diligence are performed to reduce risks before entering into formal supplier or other third-party relationships | F28: 3 | G28: Due diligence questionnaires are completed for new critical suppliers before onboarding. | H28: Supplier Due Diligence Questionnaire
A29: Govern | B29: GV.SC | C29: Cybersecurity Supply Chain Risk Management | D29: GV.SC-07 | E29: The risks posed by a supplier, their products and services, and other third parties are understood, recorded, prioritized, assessed, responded to, and monitored over the course of the relationship | F29: 3 | G29: Ongoing supplier risk is recorded and reviewed annually for critical-tier vendors, though non-critical vendors are reviewed on an ad hoc basis. | H29: Vendor List / Vendor Review Log
A30: Govern | B30: GV.SC | C30: Cybersecurity Supply Chain Risk Management | D30: GV.SC-08 | E30: Relevant suppliers and other third parties are included in incident planning, response, and recovery activities | F30: 2 | G30: Critical suppliers are named in vendor contracts but are not formally included in incident response or recovery plan testing exercises. | H30: IR Plan (gap noted) | I30: Are suppliers, e.g. the core banking hosting provider, included in any incident response tabletop exercises?
A31: Govern | B31: GV.SC | C31: Cybersecurity Supply Chain Risk Management | D31: GV.SC-09 | E31: Supply chain security practices are integrated into cybersecurity and enterprise risk management programs, and their performance is monitored throughout the technology product and service life cycle | F31: 2 | G31: Supply chain security expectations are set at contract signing but ongoing performance against them is not systematically monitored through the vendor lifecycle. | H31: Vendor Risk Management Policy | I31: How is supplier security performance monitored after contract signature, if at all?
A32: Govern | B32: GV.SC | C32: Cybersecurity Supply Chain Risk Management | D32: GV.SC-10 | E32: Cybersecurity supply chain risk management plans include provisions for activities that occur after the conclusion of a partnership or service agreement | F32: 2 | G32: Contracts do not consistently include provisions covering data return, deletion, or access revocation at the end of a supplier relationship. | H32: Standard Supplier Contract Template | I32: What happens to data access and return obligations when a supplier relationship ends?
A33: Identify | B33: ID.AM | C33: Asset Management | D33: ID.AM-01 | E33: Inventories of hardware managed by the organization are maintained | F33: 3 | G33: Hardware inventory for the legacy core banking estate is well-maintained via the IT asset management system; general insurance SaaS platform hardware is out of scope since it is vendor-hosted. | H33: Asset Inventory (10-20 rows)
A34: Identify | B34: ID.AM | C34: Asset Management | D34: ID.AM-02 | E34: Inventories of software, services, and systems managed by the organization are maintained | F34: 2 | G34: Software, services and systems are inventoried, but the SaaS insurance platform's underlying service dependencies are not fully catalogued. | H34: Asset Inventory | I34: Is there a software/service inventory covering the SaaS insurance platform's dependencies?
A35: Identify | B35: ID.AM | C35: Asset Management | D35: ID.AM-03 | E35: Representations of the organization's authorized network communication and internal and external network data flows are maintained | F35: 2 | G35: Network diagrams exist for the on-prem core banking environment; data flows to and from the SaaS insurance platform are not formally mapped. | H35: Network Architecture Diagram | I35: Is there a data flow diagram covering traffic between core banking and the SaaS insurance platform?
A36: Identify | B36: ID.AM | C36: Asset Management | D36: ID.AM-04 | E36: Inventories of services provided by suppliers are maintained | F36: 2 | G36: Supplier-provided services are listed in the vendor list but not cross-referenced against the asset inventory. | H36: Vendor List
A37: Identify | B37: ID.AM | C37: Asset Management | D37: ID.AM-05 | E37: Assets are prioritized based on classification, criticality, resources, and impact on the mission | F37: 2 | G37: Assets are classified by criticality in the asset inventory, though the classification scheme is applied inconsistently between BUs. | H37: Asset Inventory / Data Classification Policy
A38: Identify | B38: ID.AM | C38: Asset Management | D38: ID.AM-07 | E38: Inventories of data and corresponding metadata for designated data types are maintained | F38: 2 | G38: A data inventory exists for regulated customer data categories, but metadata (retention period, classification, owner) is incomplete for a portion of records. | H38: Data Classification Policy
A39: Identify | B39: ID.AM | C39: Asset Management | D39: ID.AM-08 | E39: Systems, hardware, software, services, and data are managed throughout their life cycles | F39: 2 | G39: Asset lifecycle management (decommissioning, disposal) is performed but not tracked centrally; the legacy core banking platform in particular lacks a documented end-of-life roadmap. | H39: Asset Inventory | I39: Is there a documented lifecycle/decommissioning plan for the core banking platform?
A40: Identify | B40: ID.RA | C40: Risk Assessment | D40: ID.RA-01 | E40: Vulnerabilities in assets are identified, validated, and recorded | F40: 2 | G40: Vulnerability scanning is performed on the core banking estate and validated findings are recorded in a vulnerability tracker; coverage of the SaaS insurance platform relies on the vendor's own disclosures. | H40: Vuln Mgmt Standard
...

Sheet Category Rollup
A1: Function | B1: Category ID | C1: Category Name | D1: Category Avg CMMI (formula) | E1: Subcategory Count
A2: Govern | B2: GV.OC | C2: Organizational Context | D2: =AVERAGEIF('Subcategory Scores'!$B:$B,"GV.OC",'Subcategory Scores'!$F:$F) -> 3 | E2: 5
A3: Govern | B3: GV.RM | C3: Risk Management Strategy | D3: =AVERAGEIF('Subcategory Scores'!$B:$B,"GV.RM",'Subcategory Scores'!$F:$F) -> 3 | E3: 7
A4: Govern | B4: GV.RR | C4: Roles, Responsibilities, and Authorities | D4: =AVERAGEIF('Subcategory Scores'!$B:$B,"GV.RR",'Subcategory Scores'!$F:$F) -> 3.5 | E4: 4 | G4: Note: A few judgment calls worth flagging PR.AA-05 is the anchor for your MFA hook, scored 1, explicitly tied to the incident log. Everything else was built to be consistent with that story rather than random — weak backup testing (PR.DS-11), thin post-incident closure criteria (RC.RP-04/06), and informal public comms during recovery (RC.CO-04) all reinforce the "policies and alarms exist, follow-through doesn't" narrative alongside Respond/Recover's flatter scores. GV.SC (supply chain) is Govern's weakest category (avg 2.5 against a function average of 3.0) — I used this to add texture to an otherwise strong Govern score, since outsourcing oversight is a very plausible soft spot even in a well-governed firm, and it gives you a natural GV.SC-08/09/10 drill-down for the demo. ~35 residual client questions is close to your "60-70 question bank" target once you add questions for the ~70 subcategories that don't have a gap (a shorter confirmatory question, or none at all if the document evidence is airtight) — you may not need a question for every one of the 106.
A5: Govern | B5: GV.PO | C5: Policy | D5: =AVERAGEIF('Subcategory Scores'!$B:$B,"GV.PO",'Subcategory Scores'!$F:$F) -> 3.5 | E5: 2
A6: Govern | B6: GV.OV | C6: Oversight | D6: =AVERAGEIF('Subcategory Scores'!$B:$B,"GV.OV",'Subcategory Scores'!$F:$F) -> 3 | E6: 3
A7: Govern | B7: GV.SC | C7: Cybersecurity Supply Chain Risk Management | D7: =AVERAGEIF('Subcategory Scores'!$B:$B,"GV.SC",'Subcategory Scores'!$F:$F) -> 2.7 | E7: 10
A8: Identify | B8: ID.AM | C8: Asset Management | D8: =AVERAGEIF('Subcategory Scores'!$B:$B,"ID.AM",'Subcategory Scores'!$F:$F) -> 2.1428571 | E8: 7
A9: Identify | B9: ID.RA | C9: Risk Assessment | D9: =AVERAGEIF('Subcategory Scores'!$B:$B,"ID.RA",'Subcategory Scores'!$F:$F) -> 1.9 | E9: 10
A10: Identify | B10: ID.IM | C10: Improvement | D10: =AVERAGEIF('Subcategory Scores'!$B:$B,"ID.IM",'Subcategory Scores'!$F:$F) -> 2 | E10: 4
A11: Protect | B11: PR.AA | C11: Identity Management, Authentication, and Access Control | D11: =AVERAGEIF('Subcategory Scores'!$B:$B,"PR.AA",'Subcategory Scores'!$F:$F) -> 2 | E11: 6
A12: Protect | B12: PR.AT | C12: Awareness and Training | D12: =AVERAGEIF('Subcategory Scores'!$B:$B,"PR.AT",'Subcategory Scores'!$F:$F) -> 2.5 | E12: 2
A13: Protect | B13: PR.DS | C13: Data Security | D13: =AVERAGEIF('Subcategory Scores'!$B:$B,"PR.DS",'Subcategory Scores'!$F:$F) -> 1.5 | E13: 4
A14: Protect | B14: PR.PS | C14: Platform Security | D14: =AVERAGEIF('Subcategory Scores'!$B:$B,"PR.PS",'Subcategory Scores'!$F:$F) -> 2.1666667 | E14: 6
A15: Protect | B15: PR.IR | C15: Technology Infrastructure Resilience | D15: =AVERAGEIF('Subcategory Scores'!$B:$B,"PR.IR",'Subcategory Scores'!$F:$F) -> 2 | E15: 4
A16: Detect | B16: DE.CM | C16: Continuous Monitoring | D16: =AVERAGEIF('Subcategory Scores'!$B:$B,"DE.CM",'Subcategory Scores'!$F:$F) -> 3 | E16: 5
A17: Detect | B17: DE.AE | C17: Adverse Event Analysis | D17: =AVERAGEIF('Subcategory Scores'!$B:$B,"DE.AE",'Subcategory Scores'!$F:$F) -> 3 | E17: 6
A18: Respond | B18: RS.MA | C18: Incident Management | D18: =AVERAGEIF('Subcategory Scores'!$B:$B,"RS.MA",'Subcategory Scores'!$F:$F) -> 2 | E18: 5
A19: Respond | B19: RS.AN | C19: Incident Analysis | D19: =AVERAGEIF('Subcategory Scores'!$B:$B,"RS.AN",'Subcategory Scores'!$F:$F) -> 2 | E19: 4
A20: Respond | B20: RS.CO | C20: Incident Response Reporting and Communication | D20: =AVERAGEIF('Subcategory Scores'!$B:$B,"RS.CO",'Subcategory Scores'!$F:$F) -> 2 | E20: 2
A21: Respond | B21: RS.MI | C21: Incident Mitigation | D21: =AVERAGEIF('Subcategory Scores'!$B:$B,"RS.MI",'Subcategory Scores'!$F:$F) -> 2 | E21: 2
A22: Recover | B22: RC.RP | C22: Incident Recovery Plan Execution | D22: =AVERAGEIF('Subcategory Scores'!$B:$B,"RC.RP",'Subcategory Scores'!$F:$F) -> 2 | E22: 6
A23: Recover | B23: RC.CO | C23: Incident Recovery Communication | D23: =AVERAGEIF('Subcategory Scores'!$B:$B,"RC.CO",'Subcategory Scores'!$F:$F) -> 2 | E23: 2

Sheet Function Summary (Tier Rollup)
A1: CSF Function | B1: Subcategory Count | C1: Function Avg CMMI (formula) | D1: Target CMMI (expert-set) | E1: Rolled-Up CSF Tier (formula)
A2: Govern | B2: 31 | C2: =AVERAGEIF('Subcategory Scores'!$A:$A,"Govern",'Subcategory Scores'!$F:$F) -> 3 | D2: 3 | E2: =IF(C2>=4,"Tier 4 (Adaptive)",IF(C2>=3,"Tier 3 (Repeatable)",IF(C2>=2,"Tier 2 (Risk Informed)","Tier 1 (Partial)"))) -> Tier 3 (Repeatable)
A3: Identify | B3: 21 | C3: =AVERAGEIF('Subcategory Scores'!$A:$A,"Identify",'Subcategory Scores'!$F:$F) -> 2 | D3: 2 | E3: =IF(C3>=4,"Tier 4 (Adaptive)",IF(C3>=3,"Tier 3 (Repeatable)",IF(C3>=2,"Tier 2 (Risk Informed)","Tier 1 (Partial)"))) -> Tier 2 (Risk Informed)
A4: Protect | B4: 22 | C4: =AVERAGEIF('Subcategory Scores'!$A:$A,"Protect",'Subcategory Scores'!$F:$F) -> 2 | D4: 2 | E4: =IF(C4>=4,"Tier 4 (Adaptive)",IF(C4>=3,"Tier 3 (Repeatable)",IF(C4>=2,"Tier 2 (Risk Informed)","Tier 1 (Partial)"))) -> Tier 2 (Risk Informed)
A5: Detect | B5: 11 | C5: =AVERAGEIF('Subcategory Scores'!$A:$A,"Detect",'Subcategory Scores'!$F:$F) -> 3 | D5: 3 | E5: =IF(C5>=4,"Tier 4 (Adaptive)",IF(C5>=3,"Tier 3 (Repeatable)",IF(C5>=2,"Tier 2 (Risk Informed)","Tier 1 (Partial)"))) -> Tier 3 (Repeatable)
A6: Respond | B6: 13 | C6: =AVERAGEIF('Subcategory Scores'!$A:$A,"Respond",'Subcategory Scores'!$F:$F) -> 2 | D6: 2 | E6: =IF(C6>=4,"Tier 4 (Adaptive)",IF(C6>=3,"Tier 3 (Repeatable)",IF(C6>=2,"Tier 2 (Risk Informed)","Tier 1 (Partial)"))) -> Tier 2 (Risk Informed)
A7: Recover | B7: 8 | C7: =AVERAGEIF('Subcategory Scores'!$A:$A,"Recover",'Subcategory Scores'!$F:$F) -> 2 | D7: 2 | E7: =IF(C7>=4,"Tier 4 (Adaptive)",IF(C7>=3,"Tier 3 (Repeatable)",IF(C7>=2,"Tier 2 (Risk Informed)","Tier 1 (Partial)"))) -> Tier 2 (Risk Informed)
A8: Org-wide (all 6 Functions) | B8: =SUM(B2:B7) -> 106 | C8: =AVERAGE(C2:C7) -> 2.3333333 | D8: =AVERAGE(D2:D7) -> 2.3333333 | E8: =IF(C8>=4,"Tier 4 (Adaptive)",IF(C8>=3,"Tier 3 (Repeatable)",IF(C8>=2,"Tier 2 (Risk Informed)","Tier 1 (Partial)"))) -> Tier 2 (Risk Informed)
A10: Note: CMMI scores in 'Subcategory Scores' are demo ground-truth assumptions (internal, not derived from real evidence). Tier is computed from the locked aggregation rule: 1.0-1.9=Tier 1, 2.0-2.9=Tier 2, 3.0-3.9=Tier 3, 4.0-5.0=Tier 4.
